Workbook
Name Slicer_Day_Name: #N/A
Name Slicer_Month: #N/A
Name Slicer_Quarter: #N/A
Name Slicer_Year: #N/A

Sheet Historical Data
A1: Name | B1: Extension | C1: Date accessed | D1: Date modified | E1: Date created | F1: Folder Path | G1: ExtractedData | H1: Date | I1: Fries_Cost | J1: Fries_Sales | K1: Fries_Profit | L1: Zinger_Cost | M1: Zinger_Sales | N1: Zinger_Profit | O1: Loaded_Food_Cost | P1: Loaded_Food_Sales | Q1: Loaded_Food_Profit | R1: Drinks_Cost | S1: Drinks_Sales | T1: Drinks_Profit | U1: Daily_Operational_Cost | V1: Total_Daily_Sales | W1: Total Gross Profit | X1: Net_Profit | AB1: Zinger_Profit_Check
A2: 02 Dec 2022.xlsx | B2: .xlsx | C2: 46258.444 | D2: 44898.052 | E2: 46258.386 | F2: E:\Ahmad\Analytical Projects\Taj-Bites-Analytic\raw-data\Dec 2022\ | G2: [Table] | H2: 44897 | I2: 7395.965 | J2: 9730 | K2: 2334.035 | L2: 2614.25 | M2: 4200 | N2: 1585.75 | O2: 641.49 | P2: 2330 | Q2: 1688.51 | R2: 771.66667 | S2: 990 | T2: 218.33333 | U2: 2100 | V2: 17250 | W2: 5826.6283 | X2: 3726.6283 | AB2: =IF(ABS(N2-(M2-L2))<0.01,"PASS","CHECK") -> PASS
A3: 03 Dec 2022.xlsx | B3: .xlsx | C3: 46258.444 | D3: 44899.018 | E3: 46258.386 | F3: E:\Ahmad\Analytical Projects\Taj-Bites-Analytic\raw-data\Dec 2022\ | G3: [Table] | H3: 44898 | I3: 9047.4 | J3: 11510 | K3: 2462.6 | L3: 1167.95 | M3: 2100 | N3: 932.05 | O3: 305 | P3: 1350 | Q3: 1045 | R3: 599.16667 | S3: 790 | T3: 190.83333 | U3: 2100 | V3: 15750 | W3: 4630.4833 | X3: 2530.4833 | AB3: =IF(ABS(N3-(M3-L3))<0.01,"PASS","CHECK") -> PASS
A4: 04 Dec 2022.xlsx | B4: .xlsx | C4: 46258.444 | D4: 44900.012 | E4: 46258.386 | F4: E:\Ahmad\Analytical Projects\Taj-Bites-Analytic\raw-data\Dec 2022\ | G4: [Table] | H4: 44899 | I4: 6657.06 | J4: 7390 | K4: 732.94 | L4: 1560.9 | M4: 2310 | N4: 749.1 | O4: 813 | P4: 1700 | Q4: 887 | R4: 740 | S4: 1000 | T4: 260 | U4: 2100 | V4: 12400 | W4: 2629.04 | X4: 529.04 | AB4: =IF(ABS(N4-(M4-L4))<0.01,"PASS","CHECK") -> PASS
A5: 05 Dec 2022.xlsx | B5: .xlsx | C5: 46258.444 | D5: 44901.019 | E5: 46258.386 | F5: E:\Ahmad\Analytical Projects\Taj-Bites-Analytic\raw-data\Dec 2022\ | G5: [Table] | H5: 44900 | I5: 6454.1 | J5: 9500 | K5: 3045.9 | L5: 2245.3 | M5: 4200 | N5: 1954.7 | O5: 333 | P5: 670 | Q5: 337 | R5: 763.33333 | S5: 1010 | T5: 246.66667 | U5: 2100 | V5: 15380 | W5: 5584.2667 | X5: 3484.2667 | AB5: =IF(ABS(N5-(M5-L5))<0.01,"PASS","CHECK") -> PASS
A6: 06 Dec 2022.xlsx | B6: .xlsx | C6: 46258.444 | D6: 44902.009 | E6: 46258.386 | F6: E:\Ahmad\Analytical Projects\Taj-Bites-Analytic\raw-data\Dec 2022\ | G6: [Table] | H6: 44901 | I6: 6140.695 | J6: 7010 | K6: 869.305 | L6: 1538.35 | M6: 3070 | N6: 1531.65 | O6: 313.45 | P6: 600 | Q6: 286.55 | R6: 760 | S6: 970 | T6: 210 | U6: 2100 | V6: 11650 | W6: 2897.505 | X6: 797.505 | AB6: =IF(ABS(N6-(M6-L6))<0.01,"PASS","CHECK") -> PASS
A7: 07 Dec 2022.xlsx | B7: .xlsx | C7: 46258.444 | D7: 44903.016 | E7: 46258.386 | F7: E:\Ahmad\Analytical Projects\Taj-Bites-Analytic\raw-data\Dec 2022\ | G7: [Table] | H7: 44902 | I7: 6554.115 | J7: 8100 | K7: 1545.885 | L7: 1836.35 | M7: 5040 | N7: 3203.65 | O7: 198.81 | P7: 300 | Q7: 101.19 | R7: 980.83333 | S7: 1290 | T7: 309.16667 | U7: 2100 | V7: 14730 | W7: 5159.8917 | X7: 3059.8917 | AB7: =IF(ABS(N7-(M7-L7))<0.01,"PASS","CHECK") -> PASS
A8: 08 Dec 2022.xlsx | B8: .xlsx | C8: 46258.444 | D8: 44904.108 | E8: 46258.386 | F8: E:\Ahmad\Analytical Projects\Taj-Bites-Analytic\raw-data\Dec 2022\ | G8: [Table] | H8: 44903 | I8: 5881.035 | J8: 6660 | K8: 778.965 | L8: 3654.8 | M8: 7140 | N8: 3485.2 | O8: 461.66 | P8: 1330 | Q8: 868.34 | R8: 750 | S8: 980 | T8: 230 | U8: 2100 | V8: 16110 | W8: 5362.505 | X8: 3262.505 | AB8: =IF(ABS(N8-(M8-L8))<0.01,"PASS","CHECK") -> PASS
A9: 09 Dec 2022.xlsx | B9: .xlsx | C9: 46258.444 | D9: 44905.033 | E9: 46258.386 | F9: E:\Ahmad\Analytical Projects\Taj-Bites-Analytic\raw-data\Dec 2022\ | G9: [Table] | H9: 44904 | I9: 5413.115 | J9: 6650 | K9: 1236.885 | L9: 1268.8 | M9: 2310 | N9: 1041.2 | O9: 178 | P9: 120 | Q9: -58 | R9: 620.83333 | S9: 830 | T9: 209.16667 | U9: 1700 | V9: 9910 | W9: 2429.2517 | X9: 729.25167 | AB9: =IF(ABS(N9-(M9-L9))<0.01,"PASS","CHECK") -> PASS
A10: 10 Dec 2022.xlsx | B10: .xlsx | C10: 46258.444 | D10: 46256.278 | E10: 46258.386 | F10: E:\Ahmad\Analytical Projects\Taj-Bites-Analytic\raw-data\Dec 2022\ | G10: [Table] | H10: 44905 | I10: 9176.72 | J10: 12000 | K10: 2823.28 | L10: 3939.75 | M10: 7560 | N10: 3620.25 | O10: 309 | P10: 2010 | Q10: 1701 | R10: 1194.1667 | S10: 1490 | T10: 295.83333 | U10: 1700 | V10: 23060 | W10: 8440.3633 | X10: 6740.3633 | AB10: =IF(ABS(N10-(M10-L10))<0.01,"PASS","CHECK") -> PASS
A11: 11 Dec 2022.xlsx | B11: .xlsx | C11: 46258.444 | D11: 44907.022 | E11: 46258.386 | F11: E:\Ahmad\Analytical Projects\Taj-Bites-Analytic\raw-data\Dec 2022\ | G11: [Table] | H11: 44906 | I11: 8557.08 | J11: 9350 | K11: 792.92 | L11: 2370.7 | M11: 4200 | N11: 1829.3 | O11: 354 | P11: 1640 | Q11: 1286 | R11: 678.33333 | S11: 910 | T11: 231.66667 | U11: 1700 | V11: 16100 | W11: 4139.8867 | X11: 2439.8867 | AB11: =IF(ABS(N11-(M11-L11))<0.01,"PASS","CHECK") -> PASS
A12: 12 Dec 2022.xlsx | B12: .xlsx | C12: 46258.444 | D12: 44908.019 | E12: 46258.386 | F12: E:\Ahmad\Analytical Projects\Taj-Bites-Analytic\raw-data\Dec 2022\ | G12: [Table] | H12: 44907 | I12: 8388.94 | J12: 10910 | K12: 2521.06 | L12: 2348.5 | M12: 3780 | N12: 1431.5 | O12: 339.15 | P12: 1460 | Q12: 1120.85 | R12: 368.33333 | S12: 400 | T12: 31.666667 | U12: 1700 | V12: 16550 | W12: 5105.0767 | X12: 3405.0767 | AB12: =IF(ABS(N12-(M12-L12))<0.01,"PASS","CHECK") -> PASS
A13: 13 Dec 2022.xlsx | B13: .xlsx | C13: 46258.444 | D13: 46256.362 | E13: 46258.386 | F13: E:\Ahmad\Analytical Projects\Taj-Bites-Analytic\raw-data\Dec 2022\ | G13: [Table] | H13: 44908 | I13: 7390.19 | J13: 9850 | K13: 2459.81 | L13: 961.95 | M13: 2100 | N13: 1138.05 | O13: 90 | P13: 750 | Q13: 660 | R13: 595 | S13: 730 | T13: 135 | U13: 2100 | V13: 13430 | W13: 4392.86 | X13: 2292.86 | AB13: =IF(ABS(N13-(M13-L13))<0.01,"PASS","CHECK") -> PASS
... A382: 31 Dec 2023.xlsx | B382: .xlsx | C382: 46258.444 | D382: 45291.942 | E382: 46258.386 | F382: E:\Ahmad\Analytical Projects\Taj-Bites-Analytic\raw-data\Dec 2023\ | G382: [Table] | H382: 45291 | I382: 1478.565 | J382: 9700 | K382: 8221.435 | L382: -366 | M382: 2300 | N382: 2666 | O382: 122.75 | P382: 600 | Q382: 477.25 | R382: 546.66667 | S382: 700 | T382: 153.33333 | U382: 2150 | V382: 13300 | W382: 11518.018 | X382: 9368.0183 | AB382: =IF(ABS(N382-(M382-L382))<0.01,"PASS","CHECK") -> PASS

Sheet Data Dictionary
A1: Column | B1: Definition | C1: Source / Logic | D1: Type
A2: Date | B2: Operating date | C2: Extracted from workbook filename | D2: Date
A3: Fries_Cost | B3: Daily fries cost | C3: Source workbook | D3: Currency
A4: Fries_Sales | B4: Daily fries sales | C4: Residual sales calculation | D4: Currency
A5: Fries_Profit | B5: Fries sales minus fries cost | C5: Derived | D5: Currency
A6: Zinger_Cost | B6: Zinger category cost | C6: Source workbook | D6: Currency
A7: Zinger_Sales | B7: Zinger category sales | C7: Source workbook | D7: Currency
A8: Zinger_Profit | B8: Zinger sales minus cost | C8: Derived | D8: Currency
A9: Loaded_Food_Cost | B9: Standardized loaded-food cost | C9: Conditional extraction | D9: Currency
A10: Loaded_Food_Sales | B10: Standardized loaded-food sales | C10: Conditional extraction | D10: Currency
A11: Loaded_Food_Profit | B11: Standardized loaded-food profit | C11: Conditional extraction | D11: Currency
A12: Drinks_Cost | B12: Daily drinks cost | C12: Source workbook | D12: Currency
A13: Drinks_Sales | B13: Daily drinks sales | C13: Source workbook | D13: Currency

Sheet Data Quality
A1: Column | B1: Blank Count | C1: Check/Status
A2: Fries Cost | B2: =COUNTBLANK(Daily_Analysis!B2:B382) -> 0 | C2: =IF(B2=0,"PASS","CHECK") -> PASS
A3: Fries Sales | B3: =COUNTBLANK('Historical Data'!J2:J382) -> 0 | C3: =IF(B3=0,"PASS","CHECK") -> PASS
A4: Fries Profit | B4: =COUNTBLANK('Historical Data'!K2:K382) -> 0 | C4: =IF(B4=0,"PASS","CHECK") -> PASS
A5: Zinger Cost | B5: =COUNTBLANK('Historical Data'!L2:L382) -> 0 | C5: =IF(B5=0,"PASS","CHECK") -> PASS
A6: Zinger Sales | B6: =COUNTBLANK('Historical Data'!M2:M382) -> 0 | C6: =IF(B6=0,"PASS","CHECK") -> PASS
A7: Zinger Profit | B7: =COUNTBLANK('Historical Data'!N2:N382) -> 0 | C7: =IF(B7=0,"PASS","CHECK") -> PASS
A8: Loaded Cost | B8: =COUNTBLANK('Historical Data'!O2:O382) -> 0 | C8: =IF(B8=0,"PASS","CHECK") -> PASS
A9: Loaded Sales | B9: =COUNTBLANK('Historical Data'!P2:P382) -> 0 | C9: =IF(B9=0,"PASS","CHECK") -> PASS
A10: Loaded Profit | B10: =COUNTBLANK('Historical Data'!Q2:Q382) -> 0 | C10: =IF(B10=0,"PASS","CHECK") -> PASS
A11: Afghani Sausage Profit | B11: =COUNTBLANK('Historical Data'!R2:R382) -> 0 | C11: =IF(B11=0,"PASS","CHECK") -> PASS
A12: Cold Drinks Cost | B12: =COUNTBLANK('Historical Data'!S2:S382) -> 0 | C12: =IF(B12=0,"PASS","CHECK") -> PASS
A13: Cold Drinks Sales | B13: =COUNTBLANK('Historical Data'!T2:T382) -> 0 | C13: =IF(B13=0,"PASS","CHECK") -> PASS
A14: Cold Drinks Profit | B14: =COUNTBLANK('Historical Data'!U2:U382) -> 0 | C14: =IF(B14=0,"PASS","CHECK") -> PASS
A15: Daily Operational Cost | B15: =COUNTBLANK('Historical Data'!V2:V382) -> 0 | C15: =IF(B15=0,"PASS","CHECK") -> PASS
A16: Total Gross Profit | B16: =COUNTBLANK('Historical Data'!W2:W382) -> 0 | C16: =IF(B16=0,"PASS","CHECK") -> PASS
A17: Net Profit | B17: =COUNTBLANK('Historical Data'!X2:X382) -> 0 | C17: =IF(B17=0,"PASS","CHECK") -> PASS
A18: Total Records | B18: =COUNTA(Daily_Analysis!A2:A382) -> 381 | C18: =IF(B18=381,"PASS","CHECK") -> PASS
A19: Duplicate Dates | B19: =COUNTA(Daily_Analysis!A2:A382)-SUMPRODUCT(1/COUNTIF(Daily_Analysis!A2:A382,Daily_Analysis!A2:A382)) -> 0 | C19: =IF(B19=0,"PASS","CHECK") -> PASS
A20: Missing Dates | B20: =MAX(Daily_Analysis!A2:A382)-MIN(Daily_Analysis!A2:A382)+1-COUNTA(Daily_Analysis!A2:A382) -> 14 | C20: =IF(B20=0,"PASS","CHECK") -> CHECK
A21: Negative Net Profit | B21: =COUNTIF(Daily_Analysis!Q2:Q382,"<0") -> 81 | C21: =IF(B21=0,"PASS","CHECK") -> CHECK
A22: Negative Gross Profit | B22: =COUNTIF(Daily_Analysis!P2:P382,"<0") -> 7 | C22: =IF(B22=0,"PASS","CHECK") -> CHECK
A23: Negative Fries Profit | B23: =COUNTIF(Daily_Analysis!D2:D382,"<0") -> 83 | C23: =IF(B23=0,"PASS","CHECK") -> CHECK
A24: Negative Zinger Profit | B24: =COUNTIF(Daily_Analysis!G2:G382,"<0") -> 18 | C24: =IF(B24=0,"PASS","CHECK") -> CHECK
A25: Negative Drinks Profit | B25: =COUNTIF(Daily_Analysis!M2:M382,"<0") -> 2 | C25: =IF(B25=0,"PASS","CHECK") -> CHECK
A26: Negative Loaded Food Profit | B26: =COUNTIF(Daily_Analysis!J2:J382,"<0") -> 17 | C26: =IF(B26=0,"PASS","CHECK") -> CHECK
A27: Fries Profit Mismatch | B27: =SUMPRODUCT(--(ABS(Daily_Analysis!D2:D382-(Daily_Analysis!C2:C382-Daily_Analysis!B2:B382))>0.01)) -> 0 | C27: =IF(B27=0,"PASS","CHECK") -> PASS
A28: Zinger Profit Mismatch | B28: =SUMPRODUCT(--(ABS(Daily_Analysis!G2:G382-(Daily_Analysis!F2:F382-Daily_Analysis!E2:E382))>0.01)) -> 1 | C28: =IF(B28=0,"PASS","CHECK") -> CHECK
A29: Loaded Food Profit Mismatch | B29: =SUMPRODUCT(--(ABS(Daily_Analysis!J2:J382-(Daily_Analysis!I2:I382-Daily_Analysis!H2:H382))>0.01)) -> 0 | C29: =IF(B29=0,"PASS","CHECK") -> PASS
A30: Drinks Profit Mismatch | B30: =SUMPRODUCT(--(ABS(Daily_Analysis!M2:M382-(Daily_Analysis!L2:L382-Daily_Analysis!K2:K382))>0.01)) -> 0 | C30: =IF(B30=0,"PASS","CHECK") -> PASS
A31: Net Profit Mismatch | B31: =SUMPRODUCT(--(ABS(Daily_Analysis!Q2:Q382-(Daily_Analysis!P2:P382-Daily_Analysis!N2:N382))>0.01)) -> 0 | C31: =IF(B31=0,"PASS","CHECK") -> PASS

Sheet Daily_Analysis
A1: Date | B1: Fries_Cost | C1: Fries_Sales | D1: Fries_Profit | E1: Zinger_Cost | F1: Zinger_Sales | G1: Zinger_Profit | H1: Loaded_Food_Cost | I1: Loaded_Food_Sales | J1: Loaded_Food_Profit | K1: Drinks_Cost | L1: Drinks_Sales | M1: Drinks_Profit | N1: Daily_Operational_Cost | O1: Total_Daily_Sales | P1: Total Gross Profit | Q1: Net_Profit | R1: Year | S1: Month | T1: Month_Number | U1: Quarter | V1: Day_Name | W1: Profit_Status | X1: Gross_Margin | Y1: Net_Margin
A2: 44897 | B2: 7395.965 | C2: 9730 | D2: 2334.035 | E2: 2614.25 | F2: 4200 | G2: 1585.75 | H2: 641.49 | I2: 2330 | J2: 1688.51 | K2: 771.66667 | L2: 990 | M2: 218.33333 | N2: 2100 | O2: 17250 | P2: 5826.6283 | Q2: 3726.6283 | R2: =YEAR(tbl_daily[[#This Row],[Date]]) -> 2022 | S2: =TEXT(tbl_daily[[#This Row],[Date]],"mmmm") -> December | T2: =MONTH(tbl_daily[[#This Row],[Date]]) -> 12 | U2: ="Q"&ROUNDUP(MONTH(tbl_daily[[#This Row],[Date]])/3,0) -> Q4 | V2: =TEXT(tbl_daily[[#This Row],[Date]],"dddd") -> Friday | W2: =IF(Q2>0,"Profitable",IF(Q2<0,"Loss","Break-even")) -> Profitable | X2: =IFERROR(P2/O2 *100,0) -> 33.777556 | Y2: =IFERROR(Q2/O2 *100,0) -> 21.603643
A3: 44898 | B3: 9047.4 | C3: 11510 | D3: 2462.6 | E3: 1167.95 | F3: 2100 | G3: 932.05 | H3: 305 | I3: 1350 | J3: 1045 | K3: 599.16667 | L3: 790 | M3: 190.83333 | N3: 2100 | O3: 15750 | P3: 4630.4833 | Q3: 2530.4833 | R3: =YEAR(tbl_daily[[#This Row],[Date]]) -> 2022 | S3: =TEXT(tbl_daily[[#This Row],[Date]],"mmmm") -> December | T3: =MONTH(tbl_daily[[#This Row],[Date]]) -> 12 | U3: ="Q"&ROUNDUP(MONTH(tbl_daily[[#This Row],[Date]])/3,0) -> Q4 | V3: =TEXT(tbl_daily[[#This Row],[Date]],"dddd") -> Saturday | W3: =IF(Q3>0,"Profitable",IF(Q3<0,"Loss","Break-even")) -> Profitable | X3: =IFERROR(P3/O3 *100,0) -> 29.399894 | Y3: =IFERROR(Q3/O3 *100,0) -> 16.066561
A4: 44899 | B4: 6657.06 | C4: 7390 | D4: 732.94 | E4: 1560.9 | F4: 2310 | G4: 749.1 | H4: 813 | I4: 1700 | J4: 887 | K4: 740 | L4: 1000 | M4: 260 | N4: 2100 | O4: 12400 | P4: 2629.04 | Q4: 529.04 | R4: =YEAR(tbl_daily[[#This Row],[Date]]) -> 2022 | S4: =TEXT(tbl_daily[[#This Row],[Date]],"mmmm") -> December | T4: =MONTH(tbl_daily[[#This Row],[Date]]) -> 12 | U4: ="Q"&ROUNDUP(MONTH(tbl_daily[[#This Row],[Date]])/3,0) -> Q4 | V4: =TEXT(tbl_daily[[#This Row],[Date]],"dddd") -> Sunday | W4: =IF(Q4>0,"Profitable",IF(Q4<0,"Loss","Break-even")) -> Profitable | X4: =IFERROR(P4/O4 *100,0) -> 21.201935 | Y4: =IFERROR(Q4/O4 *100,0) -> 4.2664516
A5: 44900 | B5: 6454.1 | C5: 9500 | D5: 3045.9 | E5: 2245.3 | F5: 4200 | G5: 1954.7 | H5: 333 | I5: 670 | J5: 337 | K5: 763.33333 | L5: 1010 | M5: 246.66667 | N5: 2100 | O5: 15380 | P5: 5584.2667 | Q5: 3484.2667 | R5: =YEAR(tbl_daily[[#This Row],[Date]]) -> 2022 | S5: =TEXT(tbl_daily[[#This Row],[Date]],"mmmm") -> December | T5: =MONTH(tbl_daily[[#This Row],[Date]]) -> 12 | U5: ="Q"&ROUNDUP(MONTH(tbl_daily[[#This Row],[Date]])/3,0) -> Q4 | V5: =TEXT(tbl_daily[[#This Row],[Date]],"dddd") -> Monday | W5: =IF(Q5>0,"Profitable",IF(Q5<0,"Loss","Break-even")) -> Profitable | X5: =IFERROR(P5/O5 *100,0) -> 36.308626 | Y5: =IFERROR(Q5/O5 *100,0) -> 22.65453
A6: 44901 | B6: 6140.695 | C6: 7010 | D6: 869.305 | E6: 1538.35 | F6: 3070 | G6: 1531.65 | H6: 313.45 | I6: 600 | J6: 286.55 | K6: 760 | L6: 970 | M6: 210 | N6: 2100 | O6: 11650 | P6: 2897.505 | Q6: 797.505 | R6: =YEAR(tbl_daily[[#This Row],[Date]]) -> 2022 | S6: =TEXT(tbl_daily[[#This Row],[Date]],"mmmm") -> December | T6: =MONTH(tbl_daily[[#This Row],[Date]]) -> 12 | U6: ="Q"&ROUNDUP(MONTH(tbl_daily[[#This Row],[Date]])/3,0) -> Q4 | V6: =TEXT(tbl_daily[[#This Row],[Date]],"dddd") -> Tuesday | W6: =IF(Q6>0,"Profitable",IF(Q6<0,"Loss","Break-even")) -> Profitable | X6: =IFERROR(P6/O6 *100,0) -> 24.871288 | Y6: =IFERROR(Q6/O6 *100,0) -> 6.8455365
A7: 44902 | B7: 6554.115 | C7: 8100 | D7: 1545.885 | E7: 1836.35 | F7: 5040 | G7: 3203.65 | H7: 198.81 | I7: 300 | J7: 101.19 | K7: 980.83333 | L7: 1290 | M7: 309.16667 | N7: 2100 | O7: 14730 | P7: 5159.8917 | Q7: 3059.8917 | R7: =YEAR(tbl_daily[[#This Row],[Date]]) -> 2022 | S7: =TEXT(tbl_daily[[#This Row],[Date]],"mmmm") -> December | T7: =MONTH(tbl_daily[[#This Row],[Date]]) -> 12 | U7: ="Q"&ROUNDUP(MONTH(tbl_daily[[#This Row],[Date]])/3,0) -> Q4 | V7: =TEXT(tbl_daily[[#This Row],[Date]],"dddd") -> Wednesday | W7: =IF(Q7>0,"Profitable",IF(Q7<0,"Loss","Break-even")) -> Profitable | X7: =IFERROR(P7/O7 *100,0) -> 35.029814 | Y7: =IFERROR(Q7/O7 *100,0) -> 20.773195
A8: 44903 | B8: 5881.035 | C8: 6660 | D8: 778.965 | E8: 3654.8 | F8: 7140 | G8: 3485.2 | H8: 461.66 | I8: 1330 | J8: 868.34 | K8: 750 | L8: 980 | M8: 230 | N8: 2100 | O8: 16110 | P8: 5362.505 | Q8: 3262.505 | R8: =YEAR(tbl_daily[[#This Row],[Date]]) -> 2022 | S8: =TEXT(tbl_daily[[#This Row],[Date]],"mmmm") -> December | T8: =MONTH(tbl_daily[[#This Row],[Date]]) -> 12 | U8: ="Q"&ROUNDUP(MONTH(tbl_daily[[#This Row],[Date]])/3,0) -> Q4 | V8: =TEXT(tbl_daily[[#This Row],[Date]],"dddd") -> Thursday | W8: =IF(Q8>0,"Profitable",IF(Q8<0,"Loss","Break-even")) -> Profitable | X8: =IFERROR(P8/O8 *100,0) -> 33.286809 | Y8: =IFERROR(Q8/O8 *100,0) -> 20.251428
A9: 44904 | B9: 5413.115 | C9: 6650 | D9: 1236.885 | E9: 1268.8 | F9: 2310 | G9: 1041.2 | H9: 178 | I9: 120 | J9: -58 | K9: 620.83333 | L9: 830 | M9: 209.16667 | N9: 1700 | O9: 9910 | P9: 2429.2517 | Q9: 729.25167 | R9: =YEAR(tbl_daily[[#This Row],[Date]]) -> 2022 | S9: =TEXT(tbl_daily[[#This Row],[Date]],"mmmm") -> December | T9: =MONTH(tbl_daily[[#This Row],[Date]]) -> 12 | U9: ="Q"&ROUNDUP(MONTH(tbl_daily[[#This Row],[Date]])/3,0) -> Q4 | V9: =TEXT(tbl_daily[[#This Row],[Date]],"dddd") -> Friday | W9: =IF(Q9>0,"Profitable",IF(Q9<0,"Loss","Break-even")) -> Profitable | X9: =IFERROR(P9/O9 *100,0) -> 24.513135 | Y9: =IFERROR(Q9/O9 *100,0) -> 7.3587454
A10: 44905 | B10: 9176.72 | C10: 12000 | D10: 2823.28 | E10: 3939.75 | F10: 7560 | G10: 3620.25 | H10: 309 | I10: 2010 | J10: 1701 | K10: 1194.1667 | L10: 1490 | M10: 295.83333 | N10: 1700 | O10: 23060 | P10: 8440.3633 | Q10: 6740.3633 | R10: =YEAR(tbl_daily[[#This Row],[Date]]) -> 2022 | S10: =TEXT(tbl_daily[[#This Row],[Date]],"mmmm") -> December | T10: =MONTH(tbl_daily[[#This Row],[Date]]) -> 12 | U10: ="Q"&ROUNDUP(MONTH(tbl_daily[[#This Row],[Date]])/3,0) -> Q4 | V10: =TEXT(tbl_daily[[#This Row],[Date]],"dddd") -> Saturday | W10: =IF(Q10>0,"Profitable",IF(Q10<0,"Loss","Break-even")) -> Profitable | X10: =IFERROR(P10/O10 *100,0) -> 36.601749 | Y10: =IFERROR(Q10/O10 *100,0) -> 29.229676
A11: 44906 | B11: 8557.08 | C11: 9350 | D11: 792.92 | E11: 2370.7 | F11: 4200 | G11: 1829.3 | H11: 354 | I11: 1640 | J11: 1286 | K11: 678.33333 | L11: 910 | M11: 231.66667 | N11: 1700 | O11: 16100 | P11: 4139.8867 | Q11: 2439.8867 | R11: =YEAR(tbl_daily[[#This Row],[Date]]) -> 2022 | S11: =TEXT(tbl_daily[[#This Row],[Date]],"mmmm") -> December | T11: =MONTH(tbl_daily[[#This Row],[Date]]) -> 12 | U11: ="Q"&ROUNDUP(MONTH(tbl_daily[[#This Row],[Date]])/3,0) -> Q4 | V11: =TEXT(tbl_daily[[#This Row],[Date]],"dddd") -> Sunday | W11: =IF(Q11>0,"Profitable",IF(Q11<0,"Loss","Break-even")) -> Profitable | X11: =IFERROR(P11/O11 *100,0) -> 25.713582 | Y11: =IFERROR(Q11/O11 *100,0) -> 15.154576
A12: 44907 | B12: 8388.94 | C12: 10910 | D12: 2521.06 | E12: 2348.5 | F12: 3780 | G12: 1431.5 | H12: 339.15 | I12: 1460 | J12: 1120.85 | K12: 368.33333 | L12: 400 | M12: 31.666667 | N12: 1700 | O12: 16550 | P12: 5105.0767 | Q12: 3405.0767 | R12: =YEAR(tbl_daily[[#This Row],[Date]]) -> 2022 | S12: =TEXT(tbl_daily[[#This Row],[Date]],"mmmm") -> December | T12: =MONTH(tbl_daily[[#This Row],[Date]]) -> 12 | U12: ="Q"&ROUNDUP(MONTH(tbl_daily[[#This Row],[Date]])/3,0) -> Q4 | V12: =TEXT(tbl_daily[[#This Row],[Date]],"dddd") -> Monday | W12: =IF(Q12>0,"Profitable",IF(Q12<0,"Loss","Break-even")) -> Profitable | X12: =IFERROR(P12/O12 *100,0) -> 30.846385 | Y12: =IFERROR(Q12/O12 *100,0) -> 20.574481
A13: 44908 | B13: 7390.19 | C13: 9850 | D13: 2459.81 | E13: 961.95 | F13: 2100 | G13: 1138.05 | H13: 90 | I13: 750 | J13: 660 | K13: 595 | L13: 730 | M13: 135 | N13: 2100 | O13: 13430 | P13: 4392.86 | Q13: 2292.86 | R13: =YEAR(tbl_daily[[#This Row],[Date]]) -> 2022 | S13: =TEXT(tbl_daily[[#This Row],[Date]],"mmmm") -> December | T13: =MONTH(tbl_daily[[#This Row],[Date]]) -> 12 | U13: ="Q"&ROUNDUP(MONTH(tbl_daily[[#This Row],[Date]])/3,0) -> Q4 | V13: =TEXT(tbl_daily[[#This Row],[Date]],"dddd") -> Tuesday | W13: =IF(Q13>0,"Profitable",IF(Q13<0,"Loss","Break-even")) -> Profitable | X13: =IFERROR(P13/O13 *100,0) -> 32.709308 | Y13: =IFERROR(Q13/O13 *100,0) -> 17.072673
... A382: 45291 | B382: 1478.565 | C382: 9700 | D382: 8221.435 | E382: -366 | F382: 2300 | G382: 2666 | H382: 122.75 | I382: 600 | J382: 477.25 | K382: 546.66667 | L382: 700 | M382: 153.33333 | N382: 2150 | O382: 13300 | P382: 11518.018 | Q382: 9368.0183 | R382: =YEAR(tbl_daily[[#This Row],[Date]]) -> 2023 | S382: =TEXT(tbl_daily[[#This Row],[Date]],"mmmm") -> December | T382: =MONTH(tbl_daily[[#This Row],[Date]]) -> 12 | U382: ="Q"&ROUNDUP(MONTH(tbl_daily[[#This Row],[Date]])/3,0) -> Q4 | V382: =TEXT(tbl_daily[[#This Row],[Date]],"dddd") -> Sunday | W382: =IF(Q382>0,"Profitable",IF(Q382<0,"Loss","Break-even")) -> Profitable | X382: =IFERROR(P382/O382 *100,0) -> 86.601642 | Y382: =IFERROR(Q382/O382 *100,0) -> 70.436228

Sheet Formula Analysis
A1: Month | B1: Total Sales
A2: January | B2: =SUMIFS(tbl_daily[Total_Daily_Sales],tbl_daily[Month],A2) -> 368140 | D2: XLOOKUP Demonstration
A3: February | B3: =SUMIFS(tbl_daily[Total_Daily_Sales],tbl_daily[Month],A3) -> 272495 | D3: Month | E3: August
A4: March | B4: =SUMIFS(tbl_daily[Total_Daily_Sales],tbl_daily[Month],A4) -> 301720 | D4: August Sales | E4: =VLOOKUP(E3,A2:B13,2,FALSE) -> 552920
A5: April | B5: =SUMIFS(tbl_daily[Total_Daily_Sales],tbl_daily[Month],A5) -> 287200
A6: May | B6: =SUMIFS(tbl_daily[Total_Daily_Sales],tbl_daily[Month],A6) -> 409160 | D6: SUMIFS — Business Questions
A7: June | B7: =SUMIFS(tbl_daily[Total_Daily_Sales],tbl_daily[Month],A7) -> 369535 | D7: August 2023 Sales | E7: =SUMIFS(tbl_daily[Total_Daily_Sales],tbl_daily[[Year ]],2023,tbl_daily[Month],"August") -> 552920
A8: July | B8: =SUMIFS(tbl_daily[Total_Daily_Sales],tbl_daily[Month],A8) -> 370380 | D8: Friday Sales | E8: =SUMIFS(tbl_daily[Total_Daily_Sales],tbl_daily[Day_Name],"Friday") -> 796385
A9: August | B9: =SUMIFS(tbl_daily[Total_Daily_Sales],tbl_daily[Month],A9) -> 552920 | D9: August 2023 Net Profit | E9: =SUMIFS(tbl_daily[Net_Profit],tbl_daily[[Year ]],2023,tbl_daily[Month],"August") -> 103240.97
A10: September | B10: =SUMIFS(tbl_daily[Total_Daily_Sales],tbl_daily[Month],A10) -> 540310 | D10: Friday Net Profit | E10: =SUMIFS(tbl_daily[Net_Profit],tbl_daily[Day_Name],"Friday") -> 122936.86
A11: October | B11: =SUMIFS(tbl_daily[Total_Daily_Sales],tbl_daily[Month],A11) -> 495990
A12: November | B12: =SUMIFS(tbl_daily[Total_Daily_Sales],tbl_daily[Month],A12) -> 398215 | D12: AVERAGEIFS — Business Questions
A13: December | B13: =SUMIFS(tbl_daily[Total_Daily_Sales],tbl_daily[Month],A13) -> 771170 | D13: Average August Daily Sales | E13: =AVERAGEIFS(tbl_daily[Total_Daily_Sales],tbl_daily[[Year ]],2023,tbl_daily[Month],"August") -> 17836.129
A14: Variance Analysis | D14: Average Friday Sales | E14: =AVERAGEIFS(tbl_daily[Total_Daily_Sales],tbl_daily[Day_Name],"Friday") -> 14479.727
A15: August Average Daily Sales | B15: =AVERAGEIFS(tbl_daily[Total_Daily_Sales],tbl_daily[[Year ]],2023,tbl_daily[Month],"August") -> 17836.129 | D15: Average Friday Net Profit | E15: =AVERAGEIFS(tbl_daily[Net_Profit],tbl_daily[Day_Name],"Friday") -> 2235.2156
A16: Overall Average Daily Sales | B16: =AVERAGE(tbl_daily[Total_Daily_Sales]) -> 13483.556
A17: Sales Variance | B17: =B15-B16 -> 4352.5726 | D17: IF / IFS — Business Logic
A18: August Average Daily Net Profit | B18: =AVERAGEIFS(tbl_daily[Net_Profit],tbl_daily[[Year ]],2023,tbl_daily[Month],"August") -> 3330.3538 | D18: August Net Profit | E18: =SUMIFS(tbl_daily[Net_Profit],tbl_daily[[Year ]],2023,tbl_daily[Month],"August") -> 103240.97
A19: Overall Average Daily Net Profit | B19: =AVERAGE(tbl_daily[Net_Profit]) -> 1669.6446 | D19: Profit Status | E19: =IF(E18>0,"Profitable",IF(E18<0,"Loss","Break-even")) -> Profitable
A20: Net Profit Variance | B20: =B18-B19 -> 1660.7092 | D20: Performance Classification | E20: =IF(E18>50000,"Excellent",IF(E18>25000,"Good",IF(E18>0,"Profitable","Loss"))) -> Excellent

Sheet PivotTables
A3: Row Labels | B3: Sales | C3: Total Fries Cost | D3: Total Zinger Cost | E3: Total Loaded Cost | F3: Total Drinks Cost | G3: TotalGross Profit | H3: Total Operational Cost | I3: Total Net Profit | J3: Sum of Gross_Margin | K3: Sum of Net_Margin
A4: 2022 | B4: 413700 | C4: 213689.94 | D4: 57805.95 | E4: 8838.16 | F4: 18431.667 | G4: 114934.28 | H4: 63800 | I4: 51134.278 | J4: 800.12323 | K4: 316.86912
A5: December | B5: 413700 | C5: 213689.94 | D5: 57805.95 | E5: 8838.16 | F5: 18431.667 | G5: 114934.28 | H5: 63800 | I5: 51134.278 | J5: 800.12323 | K5: 316.86912
A6: 2023 | B6: 4723535 | C6: 1855519.9 | D6: 764545.19 | E6: 125345.34 | F6: 599225 | G6: 1379417 | H6: 794416.67 | I6: 585000.32 | J6: 9708.3517 | K6: 2758.9641
A7: January | B7: 368140 | C7: 164610.88 | D7: 56506.425 | E7: 7122.91 | F7: 16822.5 | G7: 123077.29 | H7: 76700 | I7: 46377.286 | J7: 1013.6624 | K7: 332.16157
A8: February | B8: 272495 | C8: 118797.52 | D8: 42316.41 | E8: 5325.75 | F8: 16164.167 | G8: 89891.158 | H8: 60200 | I8: 29691.158 | J8: 845.01757 | K8: 257.12771
A9: March | B9: 301720 | C9: 128587.94 | D9: 41529.9 | E9: 5290.66 | F9: 32897.5 | G9: 93414 | H9: 70733.333 | I9: 22680.667 | J9: 887.01393 | K9: 6.781792
A10: April | B10: 287200 | C10: 107287.5 | D10: 41214.7 | E10: 3910.9 | F10: 37793.333 | G10: 96993.562 | H10: 69500 | I10: 27493.562 | J10: 816.08625 | K10: -270.47675
A11: May | B11: 409160 | C11: 163830.81 | D11: 59480 | E11: 6421.07 | F11: 52989.167 | G11: 126438.96 | H11: 71816.667 | I11: 54622.292 | J11: 918.88275 | K11: 347.39382
A12: June | B12: 369535 | C12: 141445.57 | D12: 52793.7 | E12: 5205.42 | F12: 69663.333 | G12: 100944.38 | H12: 62550 | I12: 38394.377 | J12: 714.48882 | K12: 232.77118
A13: July | B13: 370380 | C13: 124768.75 | D13: 58350.82 | E13: 2773.25 | F13: 62945 | G13: 121542.18 | H13: 55600 | I13: 65942.184 | J13: 770.01221 | K13: 398.39775
A14: August | B14: 552920 | C14: 178735.37 | D14: 96430.7 | E14: 4954.6325 | F14: 100241.67 | G14: 172557.64 | H14: 69316.667 | I14: 103240.97 | J14: 946.35912 | K14: 543.96368
A15: September | B15: 540310 | C15: 176421.35 | D15: 96846.21 | E15: 19343.92 | F15: 85593.333 | G15: 162105.18 | H15: 60200 | I15: 101905.18 | J15: 821.45887 | K15: 498.13161
A16: October | B16: 495990 | C16: 199937.38 | D16: 85069.865 | E16: 27708 | F16: 53360 | G16: 129914.75 | H16: 66650 | I16: 63264.755 | J16: 782.28543 | K16: 348.19852
A17: November | B17: 398215 | C17: 177077.98 | D17: 65912.72 | E17: 22687.89 | F17: 42238.333 | G17: 90298.082 | H17: 64500 | I17: 25798.082 | J17: 650.12485 | K17: 135.13204
A18: December | B18: 357470 | C18: 174018.84 | D18: 68093.74 | E18: 14600.94 | F18: 28516.667 | G18: 72239.81 | H18: 66650 | I18: 5589.8103 | J18: 542.95956 | K18: -70.61887
A19: Grand Total | B19: 5137235 | C19: 2069209.8 | D19: 822351.14 | E19: 134183.5 | F19: 617656.67 | G19: 1494351.3 | H19: 858216.67 | I19: 636134.6 | J19: 10508.475 | K19: 3075.8332
A21: Day_Name | B21: Avg Sales | C21: Avg Gross Profit | D21: Avg Net Profit
A22: Sunday | B22: 14049.074 | C22: 4007.4124 | D22: 1764.5111
A23: Monday | B23: 13009.455 | C23: 3564.7824 | D23: 1320.54
A24: Tuesday | B24: 12551.091 | C24: 3393.5442 | D24: 1127.4836
A25: Wednesday | B25: 13148.182 | C25: 4017.0363 | D25: 1750.9757
A26: Thursday | B26: 12887.5 | C26: 3743.54 | D26: 1481.503
A27: Friday | B27: 14479.727 | C27: 4479.761 | D27: 2235.2156
A28: Saturday | B28: 14288.585 | C28: 4259.774 | D28: 2018.2646
A29: Grand Total | B29: 13483.556 | C29: 3922.1818 | D29: 1669.6446
A31: Profit_Status | B31: Days | C31: Sales | D31: Net Profit
A32: Loss | B32: 81 | C32: 697225 | D32: -87312.866
A33: Profitable | B33: 300 | C33: 4440010 | D33: 723447.47
A34: Grand Total | B34: 381 | C34: 5137235 | D34: 636134.6
A36: Operating Days | B36: Date Count | C36: Sales | D36: Gross Profit | E36: Net Profit
A37: 2022 | B37: 30 | C37: 413700 | D37: 114934.28 | E37: 51134.278
A38: December | B38: 30 | C38: 413700 | D38: 114934.28 | E38: 51134.278
A39: 2023 | B39: 351 | C39: 4723535 | D39: 1379417 | E39: 585000.32
A40: January | B40: 31 | C40: 368140 | D40: 123077.29 | E40: 46377.286
A41: February | B41: 26 | C41: 272495 | D41: 89891.158 | E41: 29691.158
A42: March | B42: 31 | C42: 301720 | D42: 93414 | E42: 22680.667
A43: April | B43: 30 | C43: 287200 | D43: 96993.562 | E43: 27493.562
A44: May | B44: 31 | C44: 409160 | D44: 126438.96 | E44: 54622.292
A45: June | B45: 27 | C45: 369535 | D45: 100944.38 | E45: 38394.377
...

Sheet Business Insights
A1: PROFITABILITY ANALYSIS
A3: Analysis of sales, gross profit, net profit, margins, and operating-day profitability from December 2022–December 2023.
A4: Key Performance Index | B4: Value | C4: Key Business findings
A5: Total Operating Days | B5: =COUNTA(tbl_daily[Date]) -> 381 | C5: 1. Overall profitability was positive. | G5: The business generated Rs. 636,134.60 net profit on Rs. 5.14 million in sales, producing a 12.38% net margin.
A6: Total Sales | B6: =SUM(tbl_daily[Total_Daily_Sales]) -> 5137235 | C6: 2. Profitability was achieved on most operating days. | G6: The business was profitable on 300 of 381 operating days (78.74%), while 81 days generated losses.
A7: Total Gross Profit | B7: =SUM(tbl_daily[Total Gross Profit]) -> 1494351.3
A8: Total Net Profit | B8: =SUM(tbl_daily[Net_Profit]) -> 636134.6 | C8: 3. August and September were the strongest profitability period. | G8: August generated Rs. 103,240.97 net profit and September generated Rs. 101,905.18.
A9: Gross Profit Margin | B9: =B7/B6 -> 0.2908863
A10: Net Profit Margin | B10: =B8/B6 -> 0.12382821 | C10: 4. December 2023 requires attention | G10: December generated Rs. 357,470 in sales but only Rs. 5,589.81 net profit, resulting in a 1.56% net margin.
A11: Profitable Days | B11: =COUNTIF(tbl_daily[Profit_Status],"Profitable") -> 300
A12: Loss Days | B12: =COUNTIF(tbl_daily[Profit_Status],"Loss") -> 81 | C12: 5. Friday was the strongest weekday | G12: Friday had the highest average sales and highest average net profit.
A13: Profitability Rate | B13: =B11/B5 -> 0.78740157 | C13: 6. Tuesday was the weakest weekday | G13: Tuesday produced the lowest average sales and lowest average net profit.
A14: Monthly profitability | F14: Weekday profitability
A15: Month | B15: Sales | C15: Gross Profit | D15: Net Profit | E15: Net Margin | F15: Day | G15: Avg Sales | H15: Avg Gross Profit | I15: Avg Net Profit
A16: January | B16: =SUMIFS(tbl_daily[Total_Daily_Sales],tbl_daily[[Year ]],2023,tbl_daily[Month],A16) -> 368140 | C16: =SUMIFS(tbl_daily[Total Gross Profit],tbl_daily[[Year ]],2023,tbl_daily[Month],A16) -> 123077.29 | D16: =SUMIFS(tbl_daily[Net_Profit],tbl_daily[[Year ]],2023,tbl_daily[Month],A16) -> 46377.286 | E16: =D16/B16 -> 0.12597731 | F16: Sunday | G16: =AVERAGEIFS(tbl_daily[Total_Daily_Sales],tbl_daily[Day_Name],F16) -> 14049.074 | H16: =AVERAGEIFS(tbl_daily[Total Gross Profit],tbl_daily[Day_Name],F16) -> 4007.4124 | I16: =AVERAGEIFS(tbl_daily[Net_Profit],tbl_daily[Day_Name],F16) -> 1764.5111
A17: February | B17: =SUMIFS(tbl_daily[Total_Daily_Sales],tbl_daily[[Year ]],2023,tbl_daily[Month],A17) -> 272495 | C17: =SUMIFS(tbl_daily[Total Gross Profit],tbl_daily[[Year ]],2023,tbl_daily[Month],A17) -> 89891.158 | D17: =SUMIFS(tbl_daily[Net_Profit],tbl_daily[[Year ]],2023,tbl_daily[Month],A17) -> 29691.158 | E17: =D17/B17 -> 0.10896038 | F17: Monday | G17: =AVERAGEIFS(tbl_daily[Total_Daily_Sales],tbl_daily[Day_Name],F17) -> 13009.455 | H17: =AVERAGEIFS(tbl_daily[Total Gross Profit],tbl_daily[Day_Name],F17) -> 3564.7824 | I17: =AVERAGEIFS(tbl_daily[Net_Profit],tbl_daily[Day_Name],F17) -> 1320.54
A18: March | B18: =SUMIFS(tbl_daily[Total_Daily_Sales],tbl_daily[[Year ]],2023,tbl_daily[Month],A18) -> 301720 | C18: =SUMIFS(tbl_daily[Total Gross Profit],tbl_daily[[Year ]],2023,tbl_daily[Month],A18) -> 93414 | D18: =SUMIFS(tbl_daily[Net_Profit],tbl_daily[[Year ]],2023,tbl_daily[Month],A18) -> 22680.667 | E18: =D18/B18 -> 0.07517124 | F18: Tuesday | G18: =AVERAGEIFS(tbl_daily[Total_Daily_Sales],tbl_daily[Day_Name],F18) -> 12551.091 | H18: =AVERAGEIFS(tbl_daily[Total Gross Profit],tbl_daily[Day_Name],F18) -> 3393.5442 | I18: =AVERAGEIFS(tbl_daily[Net_Profit],tbl_daily[Day_Name],F18) -> 1127.4836
A19: April | B19: =SUMIFS(tbl_daily[Total_Daily_Sales],tbl_daily[[Year ]],2023,tbl_daily[Month],A19) -> 287200 | C19: =SUMIFS(tbl_daily[Total Gross Profit],tbl_daily[[Year ]],2023,tbl_daily[Month],A19) -> 96993.562 | D19: =SUMIFS(tbl_daily[Net_Profit],tbl_daily[[Year ]],2023,tbl_daily[Month],A19) -> 27493.562 | E19: =D19/B19 -> 0.095729672 | F19: Wednesday | G19: =AVERAGEIFS(tbl_daily[Total_Daily_Sales],tbl_daily[Day_Name],F19) -> 13148.182 | H19: =AVERAGEIFS(tbl_daily[Total Gross Profit],tbl_daily[Day_Name],F19) -> 4017.0363 | I19: =AVERAGEIFS(tbl_daily[Net_Profit],tbl_daily[Day_Name],F19) -> 1750.9757
A20: May | B20: =SUMIFS(tbl_daily[Total_Daily_Sales],tbl_daily[[Year ]],2023,tbl_daily[Month],A20) -> 409160 | C20: =SUMIFS(tbl_daily[Total Gross Profit],tbl_daily[[Year ]],2023,tbl_daily[Month],A20) -> 126438.96 | D20: =SUMIFS(tbl_daily[Net_Profit],tbl_daily[[Year ]],2023,tbl_daily[Month],A20) -> 54622.292 | E20: =D20/B20 -> 0.13349861 | F20: Thursday | G20: =AVERAGEIFS(tbl_daily[Total_Daily_Sales],tbl_daily[Day_Name],F20) -> 12887.5 | H20: =AVERAGEIFS(tbl_daily[Total Gross Profit],tbl_daily[Day_Name],F20) -> 3743.54 | I20: =AVERAGEIFS(tbl_daily[Net_Profit],tbl_daily[Day_Name],F20) -> 1481.503
A21: June | B21: =SUMIFS(tbl_daily[Total_Daily_Sales],tbl_daily[[Year ]],2023,tbl_daily[Month],A21) -> 369535 | C21: =SUMIFS(tbl_daily[Total Gross Profit],tbl_daily[[Year ]],2023,tbl_daily[Month],A21) -> 100944.38 | D21: =SUMIFS(tbl_daily[Net_Profit],tbl_daily[[Year ]],2023,tbl_daily[Month],A21) -> 38394.377 | E21: =D21/B21 -> 0.10389916 | F21: Friday | G21: =AVERAGEIFS(tbl_daily[Total_Daily_Sales],tbl_daily[Day_Name],F21) -> 14479.727 | H21: =AVERAGEIFS(tbl_daily[Total Gross Profit],tbl_daily[Day_Name],F21) -> 4479.761 | I21: =AVERAGEIFS(tbl_daily[Net_Profit],tbl_daily[Day_Name],F21) -> 2235.2156
A22: July | B22: =SUMIFS(tbl_daily[Total_Daily_Sales],tbl_daily[[Year ]],2023,tbl_daily[Month],A22) -> 370380 | C22: =SUMIFS(tbl_daily[Total Gross Profit],tbl_daily[[Year ]],2023,tbl_daily[Month],A22) -> 121542.18 | D22: =SUMIFS(tbl_daily[Net_Profit],tbl_daily[[Year ]],2023,tbl_daily[Month],A22) -> 65942.184 | E22: =D22/B22 -> 0.17803927 | F22: Saturday | G22: =AVERAGEIFS(tbl_daily[Total_Daily_Sales],tbl_daily[Day_Name],F22) -> 14288.585 | H22: =AVERAGEIFS(tbl_daily[Total Gross Profit],tbl_daily[Day_Name],F22) -> 4259.774 | I22: =AVERAGEIFS(tbl_daily[Net_Profit],tbl_daily[Day_Name],F22) -> 2018.2646
A23: August | B23: =SUMIFS(tbl_daily[Total_Daily_Sales],tbl_daily[[Year ]],2023,tbl_daily[Month],A23) -> 552920 | C23: =SUMIFS(tbl_daily[Total Gross Profit],tbl_daily[[Year ]],2023,tbl_daily[Month],A23) -> 172557.64 | D23: =SUMIFS(tbl_daily[Net_Profit],tbl_daily[[Year ]],2023,tbl_daily[Month],A23) -> 103240.97 | E23: =D23/B23 -> 0.18671954 | F23: Profitability Status
A24: September | B24: =SUMIFS(tbl_daily[Total_Daily_Sales],tbl_daily[[Year ]],2023,tbl_daily[Month],A24) -> 540310 | C24: =SUMIFS(tbl_daily[Total Gross Profit],tbl_daily[[Year ]],2023,tbl_daily[Month],A24) -> 162105.18 | D24: =SUMIFS(tbl_daily[Net_Profit],tbl_daily[[Year ]],2023,tbl_daily[Month],A24) -> 101905.18 | E24: =D24/B24 -> 0.18860503 | F24: Profit Status | G24: Profitable Days | H24: Profitable Sales | I24: Profitable Net Profit
A25: October | B25: =SUMIFS(tbl_daily[Total_Daily_Sales],tbl_daily[[Year ]],2023,tbl_daily[Month],A25) -> 495990 | C25: =SUMIFS(tbl_daily[Total Gross Profit],tbl_daily[[Year ]],2023,tbl_daily[Month],A25) -> 129914.75 | D25: =SUMIFS(tbl_daily[Net_Profit],tbl_daily[[Year ]],2023,tbl_daily[Month],A25) -> 63264.755 | E25: =D25/B25 -> 0.12755248 | F25: Profitable | G25: =COUNTIF(tbl_daily[Profit_Status],"Profitable") -> 300 | H25: =SUMIFS(tbl_daily[Total_Daily_Sales],tbl_daily[Profit_Status],"Profitable") -> 4440010 | I25: =SUMIFS(tbl_daily[Net_Profit],tbl_daily[Profit_Status],"Profitable") -> 723447.47
A26: November | B26: =SUMIFS(tbl_daily[Total_Daily_Sales],tbl_daily[[Year ]],2023,tbl_daily[Month],A26) -> 398215 | C26: =SUMIFS(tbl_daily[Total Gross Profit],tbl_daily[[Year ]],2023,tbl_daily[Month],A26) -> 90298.082 | D26: =SUMIFS(tbl_daily[Net_Profit],tbl_daily[[Year ]],2023,tbl_daily[Month],A26) -> 25798.082 | E26: =D26/B26 -> 0.064784304 | F26: Loss | G26: =COUNTIF(tbl_daily[Profit_Status],"Loss") -> 81 | H26: =SUMIFS(tbl_daily[Total_Daily_Sales],tbl_daily[Profit_Status],"Loss") -> 697225 | I26: =SUMIFS(tbl_daily[Net_Profit],tbl_daily[Profit_Status],"Loss") -> -87312.866
A27: December | B27: =SUMIFS(tbl_daily[Total_Daily_Sales],tbl_daily[[Year ]],2023,tbl_daily[Month],A27) -> 357470 | C27: =SUMIFS(tbl_daily[Total Gross Profit],tbl_daily[[Year ]],2023,tbl_daily[Month],A27) -> 72239.81 | D27: =SUMIFS(tbl_daily[Net_Profit],tbl_daily[[Year ]],2023,tbl_daily[Month],A27) -> 5589.8103 | E27: =D27/B27 -> 0.015637145 | F27: Total | G27: =SUM(G25:G26) -> 381 | H27: =SUM(H25:H26) -> 5137235 | I27: =SUM(I25:I26) -> 636134.6

Sheet Executive Dashboard
A1: TAJ BITES
A2: Restaurant Business Performance Dashboard
A3: December 2022 – December 2023 | 381 Operating Days
A5: TOTAL SALES | C5: GROSS PROFIT | E5: NET PROFIT | G5: NET MARGIN | I5: PROFITABLE DAYS | K5: PROFITABILITY RATE
A6: PKR 5,137,235 | C6: PKR 1,494,351 | E6: PKR 636,135 | G6: 0.1238 | I6: 300 / 381 | K6: 0.7874
A9: Monthly Net Profit — 2023 | F9: Average Net Profit by Weekday
A10: Net profit performance across the 12 operating months of 2023. | F10: Average Net Profit Represented by Each Day of the Week
A25: August and September generated the strongest monthly net profit; December was substantially weaker. | F25: KEY TAKEAWAYS
A26: PROFITABILITY STATUS | E26: 1. Overall profitability was positive. 1. Overall profitability was positive. | H26: The business generated Rs. 636,134.60 net profit on Rs. 5.14 million in sales, producing a 12.38% net margin.
E27: 2. Profitability was achieved on most operating days. | H27: The business was profitable on 300 of 381 operating days (78.74%), while 81 days generated losses.
A28: Profit Status | B28: Days | C28: Sales | D28: Net Profit
E29: 3. August and September were the strongest profitability period. | H29: August generated Rs. 103,240.97 net profit and September generated Rs. 101,905.18.
A30: Profitable | B30: 300 | C30: PKR 4,440,010 | D30: PKR 723,447.47
E31: 4. December 2023 requires attention | H31: December generated Rs. 357,470 in sales but only Rs. 5,589.81 net profit, resulting in a 1.56% net margin.
A32: Loss | B32: 81 | C32: PKR 697,225 | D32: -PKR 87,312.87
E33: 5. Friday was the strongest weekday | H33: Friday had the highest average sales and highest average net profit.
A34: Total | B34: 381 | C34: PKR 5,137,235 | D34: PKR 636,134.60
E35: 6. Tuesday was the weakest weekday | H35: Tuesday produced the lowest average sales and lowest average net profit.
A36: 300 of 381 operating days were profitable.
